<?xml version="1.0" ?>
<!-- =================================================================================== -->
<!-- |    This document was autogenerated by xacro from /home/nihat/catkin_ws/src/arm_description/urdf/arm.xacro | -->
<!-- |    EDITING THIS FILE BY HAND IS NOT RECOMMENDED                                 | -->
<!-- =================================================================================== -->
<robot name="arm">
    <material name="silver">
        <color rgba="0.700 0.700 0.700 1.000" />
    </material>
    <transmission name="D1_tran">
        <type>transmission_interface/SimpleTransmission</type>
        <joint name="D1">
            <hardwareInterface>hardware_interface/EffortJointInterface</hardwareInterface>
        </joint>
        <actuator name="D1_actr">
            <hardwareInterface>hardware_interface/EffortJointInterface</hardwareInterface>
            <mechanicalReduction>1</mechanicalReduction>
        </actuator>
    </transmission>
    <transmission name="D2_tran">
        <type>transmission_interface/SimpleTransmission</type>
        <joint name="D2">
            <hardwareInterface>hardware_interface/EffortJointInterface</hardwareInterface>
        </joint>
        <actuator name="D2_actr">
            <hardwareInterface>hardware_interface/EffortJointInterface</hardwareInterface>
            <mechanicalReduction>1</mechanicalReduction>
        </actuator>
    </transmission>
    <transmission name="D3_tran">
        <type>transmission_interface/SimpleTransmission</type>
        <joint name="D3">
            <hardwareInterface>hardware_interface/EffortJointInterface</hardwareInterface>
        </joint>
        <actuator name="D3_actr">
            <hardwareInterface>hardware_interface/EffortJointInterface</hardwareInterface>
            <mechanicalReduction>1</mechanicalReduction>
        </actuator>
    </transmission>
    <transmission name="D4_tran">
        <type>transmission_interface/SimpleTransmission</type>
        <joint name="D4">
            <hardwareInterface>hardware_interface/EffortJointInterface</hardwareInterface>
        </joint>
        <actuator name="D4_actr">
            <hardwareInterface>hardware_interface/EffortJointInterface</hardwareInterface>
            <mechanicalReduction>1</mechanicalReduction>
        </actuator>
    </transmission>
    <transmission name="Slider_5_tran">
        <type>transmission_interface/SimpleTransmission</type>
        <joint name="Slider_5">
            <hardwareInterface>hardware_interface/EffortJointInterface</hardwareInterface>
        </joint>
        <actuator name="Slider_5_actr">
            <hardwareInterface>hardware_interface/EffortJointInterface</hardwareInterface>
            <mechanicalReduction>1</mechanicalReduction>
        </actuator>
    </transmission>
    <transmission name="Slider_6_tran">
        <type>transmission_interface/SimpleTransmission</type>
        <joint name="Slider_6">
            <hardwareInterface>hardware_interface/EffortJointInterface</hardwareInterface>
        </joint>
        <actuator name="Slider_6_actr">
            <hardwareInterface>hardware_interface/EffortJointInterface</hardwareInterface>
            <mechanicalReduction>1</mechanicalReduction>
        </actuator>
    </transmission>
    <gazebo>
        <plugin filename="libgazebo_ros_control.so" name="control" />
        <plugin name="gazebo_ros_control">
            <robotNamespace>/</robotNamespace>
        </plugin>
    </gazebo>
    <gazebo reference="base_link">
        <material>Gazebo/Silver</material>
        <mu1>0.2</mu1>
        <mu2>0.2</mu2>
        <selfCollide>true</selfCollide>
        <gravity>true</gravity>
    </gazebo>
    <gazebo reference="Platform_1">
        <material>Gazebo/Silver</material>
        <mu1>0.2</mu1>
        <mu2>0.2</mu2>
        <selfCollide>true</selfCollide>
    </gazebo>
    <gazebo reference="D2_1">
        <material>Gazebo/Silver</material>
        <mu1>0.2</mu1>
        <mu2>0.2</mu2>
        <selfCollide>true</selfCollide>
    </gazebo>
    <gazebo reference="D3_1">
        <material>Gazebo/Silver</material>
        <mu1>0.2</mu1>
        <mu2>0.2</mu2>
        <selfCollide>true</selfCollide>
    </gazebo>
    <gazebo reference="D4_1">
        <material>Gazebo/Silver</material>
        <mu1>0.2</mu1>
        <mu2>0.2</mu2>
        <selfCollide>true</selfCollide>
    </gazebo>
    <gazebo reference="Finger_1_1">
        <material>Gazebo/Silver</material>
        <mu1>0.2</mu1>
        <mu2>0.2</mu2>
        <selfCollide>true</selfCollide>
    </gazebo>
    <gazebo reference="Finger_2_1">
        <material>Gazebo/Silver</material>
        <mu1>0.2</mu1>
        <mu2>0.2</mu2>
        <selfCollide>true</selfCollide>
    </gazebo>
    <link name="base_link">
        <inertial>
            <origin rpy="0 0 0" xyz="0.0 0.0 0.0125" />
            <mass value="0.5548838024402973" />
            <inertia ixx="0.000154" ixy="-0.0" ixz="0.0" iyy="0.000154" iyz="0.0" izz="0.00025" />
        </inertial>
        <visual>
            <origin rpy="0 0 0" xyz="0 0 0" />
            <geometry>
                <mesh filename="package://arm_description/meshes/base_link.stl" scale="0.001 0.001 0.001" />
            </geometry>
            <material name="silver" />
        </visual>
        <collision>
            <origin rpy="0 0 0" xyz="0 0 0" />
            <geometry>
                <mesh filename="package://arm_description/meshes/base_link.stl" scale="0.001 0.001 0.001" />
            </geometry>
        </collision>
    </link>
    <link name="Platform_1">
        <inertial>
            <origin rpy="0 0 0" xyz="1.2106877832099407e-14 8.586438178793906e-18 0.024342559907098243" />
            <mass value="2.0787238143023408" />
            <inertia ixx="0.00147" ixy="-0.0" ixz="0.0" iyy="0.003108" iyz="0.0" izz="0.003539" />
        </inertial>
        <visual>
            <origin rpy="0 0 0" xyz="-0.0 -0.0 -0.025" />
            <geometry>
                <mesh filename="package://arm_description/meshes/Platform_1.stl" scale="0.001 0.001 0.001" />
            </geometry>
            <material name="silver" />
        </visual>
        <collision>
            <origin rpy="0 0 0" xyz="-0.0 -0.0 -0.025" />
            <geometry>
                <mesh filename="package://arm_description/meshes/Platform_1.stl" scale="0.001 0.001 0.001" />
            </geometry>
        </collision>
    </link>
    <link name="D2_1">
        <inertial>
            <origin rpy="0 0 0" xyz="0.015 0.0 0.08469568327292498" />
            <mass value="0.6577489881478827" />
            <inertia ixx="0.006402" ixy="-0.0" ixz="-0.0" iyy="0.006409" iyz="-0.0" izz="0.000181" />
        </inertial>
        <visual>
            <origin rpy="0 0 0" xyz="0.015 -0.0 -0.0625" />
            <geometry>
                <mesh filename="package://arm_description/meshes/D2_1.stl" scale="0.001 0.001 0.001" />
            </geometry>
            <material name="silver" />
        </visual>
        <collision>
            <origin rpy="0 0 0" xyz="0.015 -0.0 -0.0625" />
            <geometry>
                <mesh filename="package://arm_description/meshes/D2_1.stl" scale="0.001 0.001 0.001" />
            </geometry>
        </collision>
    </link>
    <link name="D3_1">
        <inertial>
            <origin rpy="0 0 0" xyz="0.014999999999999958 -1.1804267164782249e-17 0.06749406762008453" />
            <mass value="0.7634276110018746" />
            <inertia ixx="0.006149" ixy="-0.0" ixz="-0.0" iyy="0.006661" iyz="-0.0" izz="0.000708" />
        </inertial>
        <visual>
            <origin rpy="0 0 0" xyz="0.015 0.0 -0.3385" />
            <geometry>
                <mesh filename="package://arm_description/meshes/D3_1.stl" scale="0.001 0.001 0.001" />
            </geometry>
            <material name="silver" />
        </visual>
        <collision>
            <origin rpy="0 0 0" xyz="0.015 0.0 -0.3385" />
            <geometry>
                <mesh filename="package://arm_description/meshes/D3_1.stl" scale="0.001 0.001 0.001" />
            </geometry>
        </collision>
    </link>
    <link name="D4_1">
        <inertial>
            <origin rpy="0 0 0" xyz="9.723077481125942e-17 0.01461192581321165 0.03300377103466645" />
            <mass value="0.03728803268567669" />
            <inertia ixx="1.5e-05" ixy="0.0" ixz="0.0" iyy="2.6e-05" iyz="-3e-06" izz="1.4e-05" />
        </inertial>
        <visual>
            <origin rpy="0 0 0" xyz="-0.0 -0.0 -0.5885" />
            <geometry>
                <mesh filename="package://arm_description/meshes/D4_1.stl" scale="0.001 0.001 0.001" />
            </geometry>
            <material name="silver" />
        </visual>
        <collision>
            <origin rpy="0 0 0" xyz="-0.0 -0.0 -0.5885" />
            <geometry>
                <mesh filename="package://arm_description/meshes/D4_1.stl" scale="0.001 0.001 0.001" />
            </geometry>
        </collision>
    </link>
    <link name="Finger_1_1">
        <inertial>
            <origin rpy="0 0 0" xyz="-0.005466749294592968 -6.938893903907228e-18 0.03199999999999992" />
            <mass value="0.044849201864543935" />
            <inertia ixx="1.6e-05" ixy="-0.0" ixz="0.0" iyy="1.6e-05" iyz="-0.0" izz="1e-06" />
        </inertial>
        <visual>
            <origin rpy="0 0 0" xyz="-0.0475 -0.0175 -0.641" />
            <geometry>
                <mesh filename="package://arm_description/meshes/Finger_1_1.stl" scale="0.001 0.001 0.001" />
            </geometry>
            <material name="silver" />
        </visual>
        <collision>
            <origin rpy="0 0 0" xyz="-0.0475 -0.0175 -0.641" />
            <geometry>
                <mesh filename="package://arm_description/meshes/Finger_1_1.stl" scale="0.001 0.001 0.001" />
            </geometry>
        </collision>
    </link>
    <link name="Finger_2_1">
        <inertial>
            <origin rpy="0 0 0" xyz="0.005466749294592975 -6.938893903907228e-18 0.03199999999999992" />
            <mass value="0.044849201864543935" />
            <inertia ixx="1.6e-05" ixy="0.0" ixz="0.0" iyy="1.6e-05" iyz="-0.0" izz="1e-06" />
        </inertial>
        <visual>
            <origin rpy="0 0 0" xyz="0.0475 -0.0175 -0.641" />
            <geometry>
                <mesh filename="package://arm_description/meshes/Finger_2_1.stl" scale="0.001 0.001 0.001" />
            </geometry>
            <material name="silver" />
        </visual>
        <collision>
            <origin rpy="0 0 0" xyz="0.0475 -0.0175 -0.641" />
            <geometry>
                <mesh filename="package://arm_description/meshes/Finger_2_1.stl" scale="0.001 0.001 0.001" />
            </geometry>
        </collision>
    </link>
    <joint name="D1" type="continuous">
        <origin rpy="0 0 0" xyz="0.0 0.0 0.025" />
        <parent link="base_link" />
        <child link="Platform_1" />
        <axis xyz="0.0 0.0 1.0" />
    </joint>
    <joint name="D2" type="continuous">
        <origin rpy="0 0 0" xyz="-0.015 0.0 0.0375" />
        <parent link="Platform_1" />
        <child link="D2_1" />
        <axis xyz="1.0 0.0 0.0" />
    </joint>
    <joint name="D3" type="continuous">
        <origin rpy="0 0 0" xyz="0.0 -0.0 0.276" />
        <parent link="D2_1" />
        <child link="D3_1" />
        <axis xyz="-1.0 0.0 0.0" />
    </joint>
    <joint name="D4" type="continuous">
        <origin rpy="0 0 0" xyz="0.015 0.0 0.25" />
        <parent link="D3_1" />
        <child link="D4_1" />
        <axis xyz="0.0 0.0 1.0" />
    </joint>
    <joint name="Slider_5" type="prismatic">
        <origin rpy="0 0 0" xyz="0.0475 0.0175 0.0525" />
        <parent link="D4_1" />
        <child link="Finger_1_1" />
        <axis xyz="1.0 0.0 0.0" />
        <limit effort="100" lower="0.0" upper="0.0" velocity="100" />
    </joint>
    <joint name="Slider_6" type="prismatic">
        <origin rpy="0 0 0" xyz="-0.0475 0.0175 0.0525" />
        <parent link="D4_1" />
        <child link="Finger_2_1" />
        <axis xyz="1.0 0.0 0.0" />
        <limit effort="100" lower="0.0" upper="0.0" velocity="100" />
    </joint>
</robot>

